Workbook

Sheet Base
A1: CPF | B1: cliente | C1: Campanha | D1: estabelecimento | E1: Data_Contrato | F1: Status | G1: Usuário | H1: Telefone | I1: Celular | J1: Situação correta | K1: Considerar | L1: AnoMes
A2: 876.631.980-34 | B2: REJANE CECILIA DA SILVA | C2: Receptiva SAN | D2: 2.13 CREDIAGORA SANTO ANGELO | E2: 46296.372 | F2: Cliente em negociaÃ§Ã£o | G2: lucimara.stiler | H2: (51)991419285 | I2: (51)994119285 | J2: =IFERROR(INDEX(validador!$B$2:$B$13,MATCH(F2,validador!$A$2:$A$13,0)),"") -> Cliente em negociação | K2: =IFERROR(INDEX(validador!$C$2:$C$13,MATCH(J2,validador!$B$2:$B$13,0)),"") -> Ligação | L2: =IF(E2="","",YEAR(E2)&""&RIGHT("0"&MONTH(E2),2)) -> 202610
A3: 592.933.570-20 | B3: SIRLEI CAMARGO KRAEMER | C3: CRUZ ALTA INSS 50 A 200 | D3: 3.03 CREDIAGORA CRUZ ALTA | E3: 46296.374 | F3: Telefone invÃ¡lido | G3: gabriele.sg | H3: (55)99615113500false | I3: (55)996151135 | J3: =IFERROR(INDEX(validador!$B$2:$B$13,MATCH(F3,validador!$A$2:$A$13,0)),"") -> Telefone inválido | K3: =IFERROR(INDEX(validador!$C$2:$C$13,MATCH(J3,validador!$B$2:$B$13,0)),"") -> Telefone inválido | L3: =IF(E3="","",YEAR(E3)&""&RIGHT("0"&MONTH(E3),2)) -> 202610
A4: 310.346.320-00 | B4: JOSE ERICO STEFFENS | C4: RECEPTIVA LOJA DIGITAL | D4: 3.04 LOJA DIGITAL | E4: 46296.375 | F4: ProspecÃ§Ã£o | G4: FERNANDA.B | H4: (55)33333365 | I4: (55)997206025 | J4: =IFERROR(INDEX(validador!$B$2:$B$13,MATCH(F4,validador!$A$2:$A$13,0)),"") -> Prospecção | K4: =IFERROR(INDEX(validador!$C$2:$C$13,MATCH(J4,validador!$B$2:$B$13,0)),"") -> Prospecção | L4: =IF(E4="","",YEAR(E4)&""&RIGHT("0"&MONTH(E4),2)) -> 202610
A5: 001.041.250-63 | B5: MARIA INEIS DE LIMA ROSA | C5: Credito Pessoal SLG | D5: 2.04 CREDIAGORA SAO LUIZ GONZAGA | E5: 46296.376 | F5: Cliente sem interesse | G5: CHAIANE.T | H5: (55)98426094300false | I5: (55)984260943 | J5: =IFERROR(INDEX(validador!$B$2:$B$13,MATCH(F5,validador!$A$2:$A$13,0)),"") -> Cliente sem interesse | K5: =IFERROR(INDEX(validador!$C$2:$C$13,MATCH(J5,validador!$B$2:$B$13,0)),"") -> Ligação | L5: =IF(E5="","",YEAR(E5)&""&RIGHT("0"&MONTH(E5),2)) -> 202610
A6: 038.715.630-56 | B6: VANESSA DA SILVA SOARES ZOTT | C6: Receptivo TMA | D6: 2.07 CREDIAGORA TRES DE MAIO | E6: 46296.376 | F6: ProspecÃ§Ã£o | G6: eduardadahlen | H6: (55)997132131 | I6: (55)997132131 | J6: =IFERROR(INDEX(validador!$B$2:$B$13,MATCH(F6,validador!$A$2:$A$13,0)),"") -> Prospecção | K6: =IFERROR(INDEX(validador!$C$2:$C$13,MATCH(J6,validador!$B$2:$B$13,0)),"") -> Prospecção | L6: =IF(E6="","",YEAR(E6)&""&RIGHT("0"&MONTH(E6),2)) -> 202610
A7: 006.227.380-97 | B7: CLARICE LESSE RODRIGUES | C7: Receptivo TMA | D7: 2.07 CREDIAGORA TRES DE MAIO | E7: 46296.378 | F7: ProspecÃ§Ã£o | G7: eduardadahlen | H7: (55)999682727 | I7: (55)999682727 | J7: =IFERROR(INDEX(validador!$B$2:$B$13,MATCH(F7,validador!$A$2:$A$13,0)),"") -> Prospecção | K7: =IFERROR(INDEX(validador!$C$2:$C$13,MATCH(J7,validador!$B$2:$B$13,0)),"") -> Prospecção | L7: =IF(E7="","",YEAR(E7)&""&RIGHT("0"&MONTH(E7),2)) -> 202610
A8: 004.349.850-74 | B8: NARA LIDIANE BRUM | C8: Receptiva SRO | D8: 2.01 CREDIAGORA SANTA ROSA | E8: 46296.379 | F8: Cliente sem margem_INSS | G8: camila.b | H8: (55)981447411 | I8: (55)981447411 | J8: =IFERROR(INDEX(validador!$B$2:$B$13,MATCH(F8,validador!$A$2:$A$13,0)),"") -> Cliente sem margem INSS | K8: =IFERROR(INDEX(validador!$C$2:$C$13,MATCH(J8,validador!$B$2:$B$13,0)),"") -> Cliente sem margem INSS | L8: =IF(E8="","",YEAR(E8)&""&RIGHT("0"&MONTH(E8),2)) -> 202610
A9: 279.690.020-72 | B9: CARLOS ADAIL SCHERER | C9: SAN INSS MARG 30 A 300 | D9: 2.13 CREDIAGORA SANTO ANGELO | E9: 46296.38 | F9: envio de whatsapp | G9: nicoli.gb | H9: (55)3313576800false | I9: (55)999029339 | J9: =IFERROR(INDEX(validador!$B$2:$B$13,MATCH(F9,validador!$A$2:$A$13,0)),"") -> Envio de Whatsapp | K9: =IFERROR(INDEX(validador!$C$2:$C$13,MATCH(J9,validador!$B$2:$B$13,0)),"") -> Envio de Whatsapp | L9: =IF(E9="","",YEAR(E9)&""&RIGHT("0"&MONTH(E9),2)) -> 202610
A10: 415.025.310-20 | B10: EMILIA DE FATIMA LEMOS PAVAO DA SILVA | C10: SAN INSS 30+ | D10: 2.13 CREDIAGORA SANTO ANGELO | E10: 46296.381 | F10: ProspecÃ§Ã£o | G10: lucimara.stiler | H10: (55)3314125300false | I10: (55)991973504 | J10: =IFERROR(INDEX(validador!$B$2:$B$13,MATCH(F10,validador!$A$2:$A$13,0)),"") -> Prospecção | K10: =IFERROR(INDEX(validador!$C$2:$C$13,MATCH(J10,validador!$B$2:$B$13,0)),"") -> Prospecção | L10: =IF(E10="","",YEAR(E10)&""&RIGHT("0"&MONTH(E10),2)) -> 202610
A11: 533.146.110-72 | B11: EVA JUSSARA NOGUEIRA | C11: Receptiva SAN | D11: 2.13 CREDIAGORA SANTO ANGELO | E11: 46296.382 | F11: ProspecÃ§Ã£o | G11: karine.reis | H11: (47)99666987500false | I11: (47)996669875 | J11: =IFERROR(INDEX(validador!$B$2:$B$13,MATCH(F11,validador!$A$2:$A$13,0)),"") -> Prospecção | K11: =IFERROR(INDEX(validador!$C$2:$C$13,MATCH(J11,validador!$B$2:$B$13,0)),"") -> Prospecção | L11: =IF(E11="","",YEAR(E11)&""&RIGHT("0"&MONTH(E11),2)) -> 202610
A12: 354.990.870-91 | B12: ADEMAR VILSON HOLZLE | C12: RECEPTIVA LOJA DIGITAL | D12: 3.04 LOJA DIGITAL | E12: 46296.382 | F12: Cliente sem interesse | G12: FERNANDA.B | H12: (55)996804677 | I12: (55)996804677 | J12: =IFERROR(INDEX(validador!$B$2:$B$13,MATCH(F12,validador!$A$2:$A$13,0)),"") -> Cliente sem interesse | K12: =IFERROR(INDEX(validador!$C$2:$C$13,MATCH(J12,validador!$B$2:$B$13,0)),"") -> Ligação | L12: =IF(E12="","",YEAR(E12)&""&RIGHT("0"&MONTH(E12),2)) -> 202610
A13: 005.671.270-79 | B13: LEONI MULLICH | C13: SAN INSS 30+ | D13: 2.13 CREDIAGORA SANTO ANGELO | E13: 46296.382 | F13: Cliente sem interesse | G13: lucimara.stiler | I13: (55)996626612 | J13: =IFERROR(INDEX(validador!$B$2:$B$13,MATCH(F13,validador!$A$2:$A$13,0)),"") -> Cliente sem interesse | K13: =IFERROR(INDEX(validador!$C$2:$C$13,MATCH(J13,validador!$B$2:$B$13,0)),"") -> Ligação | L13: =IF(E13="","",YEAR(E13)&""&RIGHT("0"&MONTH(E13),2)) -> 202610
A14: 006.227.380-97 | B14: CLARICE LESSE RODRIGUES | C14: Receptivo TMA | D14: 2.07 CREDIAGORA TRES DE MAIO | E14: 46296.382 | F14: ProspecÃ§Ã£o | G14: eduardadahlen | H14: (55)999682727 | I14: (55)999682727 | J14: =IFERROR(INDEX(validador!$B$2:$B$13,MATCH(F14,validador!$A$2:$A$13,0)),"") -> Prospecção | K14: =IFERROR(INDEX(validador!$C$2:$C$13,MATCH(J14,validador!$B$2:$B$13,0)),"") -> Prospecção | L14: =IF(E14="","",YEAR(E14)&""&RIGHT("0"&MONTH(E14),2)) -> 202610
A15: 214.127.400-10 | B15: UGO MACHADO | C15: Receptivo SCR | D15: 2.05 CREDIAGORA SANTO CRISTO | E15: 46296.384 | F15: ProspecÃ§Ã£o | G15: patricia.eu | H15: (55)999466340 | I15: (55)999466340 | J15: =IFERROR(INDEX(validador!$B$2:$B$13,MATCH(F15,validador!$A$2:$A$13,0)),"") -> Prospecção | K15: =IFERROR(INDEX(validador!$C$2:$C$13,MATCH(J15,validador!$B$2:$B$13,0)),"") -> Prospecção | L15: =IF(E15="","",YEAR(E15)&""&RIGHT("0"&MONTH(E15),2)) -> 202610
A16: 360.872.030-87 | B16: JANDIRA OLIVEIRA BOTTEGA | C16: CRUZ ALTA INSS 50 A 200 | D16: 3.03 CREDIAGORA CRUZ ALTA | E16: 46296.384 | F16: envio de whatsapp | G16: gabriele.sg | H16: (55)99717395600false | I16: (55)997173956 | J16: =IFERROR(INDEX(validador!$B$2:$B$13,MATCH(F16,validador!$A$2:$A$13,0)),"") -> Envio de Whatsapp | K16: =IFERROR(INDEX(validador!$C$2:$C$13,MATCH(J16,validador!$B$2:$B$13,0)),"") -> Envio de Whatsapp | L16: =IF(E16="","",YEAR(E16)&""&RIGHT("0"&MONTH(E16),2)) -> 202610
A17: 607.257.700-82 | B17: NILDA MARIA DA SILVA ADOLPHO | C17: Receptiva TPO | D17: 2.14 CREDIAGORA TENENTE PORTELA | E17: 46296.384 | F17: Cliente sem margem_INSS | G17: mirian.silveira | H17: (51)982624349 | J17: =IFERROR(INDEX(validador!$B$2:$B$13,MATCH(F17,validador!$A$2:$A$13,0)),"") -> Cliente sem margem INSS | K17: =IFERROR(INDEX(validador!$C$2:$C$13,MATCH(J17,validador!$B$2:$B$13,0)),"") -> Cliente sem margem INSS | L17: =IF(E17="","",YEAR(E17)&""&RIGHT("0"&MONTH(E17),2)) -> 202610
A18: 008.086.970-05 | B18: JULIA EMILIO | C18: TPO INSS 50,00 A 150,00 | D18: 2.14 CREDIAGORA TENENTE PORTELA | E18: 46296.386 | F18: Cliente com restriÃ§Ã£o | G18: kelen.tnp | H18: (55)99973116600false | I18: (55)997337605 | J18: =IFERROR(INDEX(validador!$B$2:$B$13,MATCH(F18,validador!$A$2:$A$13,0)),"") -> Cliente com restrição | K18: =IFERROR(INDEX(validador!$C$2:$C$13,MATCH(J18,validador!$B$2:$B$13,0)),"") -> Cliente com restrição | L18: =IF(E18="","",YEAR(E18)&""&RIGHT("0"&MONTH(E18),2)) -> 202610
A19: 346.835.180-15 | B19: SENAIDE SCHROER | C19: CRUZ ALTA INSS 50 A 200 | D19: 3.03 CREDIAGORA CRUZ ALTA | E19: 46296.387 | F19: Cliente sem interesse | G19: gabriele.sg | H19: (55)991541106020false | I19: (55)991541106 | J19: =IFERROR(INDEX(validador!$B$2:$B$13,MATCH(F19,validador!$A$2:$A$13,0)),"") -> Cliente sem interesse | K19: =IFERROR(INDEX(validador!$C$2:$C$13,MATCH(J19,validador!$B$2:$B$13,0)),"") -> Ligação | L19: =IF(E19="","",YEAR(E19)&""&RIGHT("0"&MONTH(E19),2)) -> 202610
A20: 022.118.170-92 | B20: MAURICIO RIBEIRO CAMARGO | C20: CLT IJUI | D20: 2.06 CREDIAGORA IJUI | E20: 46296.388 | F20: ProspecÃ§Ã£o | G20: camila.froes | H20: (0)0 | I20: (55)991799076 | J20: =IFERROR(INDEX(validador!$B$2:$B$13,MATCH(F20,validador!$A$2:$A$13,0)),"") -> Prospecção | K20: =IFERROR(INDEX(validador!$C$2:$C$13,MATCH(J20,validador!$B$2:$B$13,0)),"") -> Prospecção | L20: =IF(E20="","",YEAR(E20)&""&RIGHT("0"&MONTH(E20),2)) -> 202610
A21: 839.745.980-49 | B21: MARI MADALENA DO NASCIMENTO | C21: TPO INSS 50,00 A 150,00 | D21: 2.14 CREDIAGORA TENENTE PORTELA | E21: 46296.389 | F21: Cliente com restriÃ§Ã£o | G21: kelen.tnp | H21: (55)35222533 | I21: (55)997324105 | J21: =IFERROR(INDEX(validador!$B$2:$B$13,MATCH(F21,validador!$A$2:$A$13,0)),"") -> Cliente com restrição | K21: =IFERROR(INDEX(validador!$C$2:$C$13,MATCH(J21,validador!$B$2:$B$13,0)),"") -> Cliente com restrição | L21: =IF(E21="","",YEAR(E21)&""&RIGHT("0"&MONTH(E21),2)) -> 202610
A22: 384.772.380-49 | B22: JOAO ADELMO LISBOA | C22: Receptivo SCR | D22: 2.05 CREDIAGORA SANTO CRISTO | E22: 46296.389 | F22: Cliente em negociaÃ§Ã£o | G22: amanda.m | H22: (55)99081800 | I22: (55)996661932 | J22: =IFERROR(INDEX(validador!$B$2:$B$13,MATCH(F22,validador!$A$2:$A$13,0)),"") -> Cliente em negociação | K22: =IFERROR(INDEX(validador!$C$2:$C$13,MATCH(J22,validador!$B$2:$B$13,0)),"") -> Ligação | L22: =IF(E22="","",YEAR(E22)&""&RIGHT("0"&MONTH(E22),2)) -> 202610
A23: 375.332.400-06 | B23: ALGEU DAGORT | C23: RECEPTIVA LOJA DIGITAL | D23: 3.04 LOJA DIGITAL | E23: 46296.389 | F23: ProspecÃ§Ã£o | G23: FERNANDA.B | H23: (55)99961803700false | I23: (55)999618037 | J23: =IFERROR(INDEX(validador!$B$2:$B$13,MATCH(F23,validador!$A$2:$A$13,0)),"") -> Prospecção | K23: =IFERROR(INDEX(validador!$C$2:$C$13,MATCH(J23,validador!$B$2:$B$13,0)),"") -> Prospecção | L23: =IF(E23="","",YEAR(E23)&""&RIGHT("0"&MONTH(E23),2)) -> 202610
A24: 308.839.700-15 | B24: ARMINDO GORAL | C24: Receptiva SRO | D24: 2.01 CREDIAGORA SANTA ROSA | E24: 46296.39 | F24: ProspecÃ§Ã£o | G24: TALIAF | H24: (55)99963165270false | I24: (55)999631652 | J24: =IFERROR(INDEX(validador!$B$2:$B$13,MATCH(F24,validador!$A$2:$A$13,0)),"") -> Prospecção | K24: =IFERROR(INDEX(validador!$C$2:$C$13,MATCH(J24,validador!$B$2:$B$13,0)),"") -> Prospecção | L24: =IF(E24="","",YEAR(E24)&""&RIGHT("0"&MONTH(E24),2)) -> 202610
A25: 012.501.740-58 | B25: DALVA BEATRIZ FEIDEN KOLLING | C25: Receptiva SRO | D25: 2.01 CREDIAGORA SANTA ROSA | E25: 46296.391 | F25: Cliente sem interesse | G25: TALIAF | H25: (55)99685327 | I25: (55)996853273 | J25: =IFERROR(INDEX(validador!$B$2:$B$13,MATCH(F25,validador!$A$2:$A$13,0)),"") -> Cliente sem interesse | K25: =IFERROR(INDEX(validador!$C$2:$C$13,MATCH(J25,validador!$B$2:$B$13,0)),"") -> Ligação | L25: =IF(E25="","",YEAR(E25)&""&RIGHT("0"&MONTH(E25),2)) -> 202610
A26: 354.990.870-91 | B26: ADEMAR VILSON HOLZLE | C26: Receptivo IJUI | D26: 2.06 CREDIAGORA IJUI | E26: 46296.391 | F26: Cliente em negociaÃ§Ã£o | G26: neusa_credi | H26: (55)996804677 | I26: (55)996804677 | J26: =IFERROR(INDEX(validador!$B$2:$B$13,MATCH(F26,validador!$A$2:$A$13,0)),"") -> Cliente em negociação | K26: =IFERROR(INDEX(validador!$C$2:$C$13,MATCH(J26,validador!$B$2:$B$13,0)),"") -> Ligação | L26: =IF(E26="","",YEAR(E26)&""&RIGHT("0"&MONTH(E26),2)) -> 202610
A27: 686.065.830-49 | B27: SUSANA MARIA DE QUADROS OLIVEIRA | C27: Receptiva SRO | D27: 2.01 CREDIAGORA SANTA ROSA | E27: 46296.391 | F27: Cliente sem margem_INSS | G27: camila.b | H27: (51)980511946020false | I27: (51)980511946 | J27: =IFERROR(INDEX(validador!$B$2:$B$13,MATCH(F27,validador!$A$2:$A$13,0)),"") -> Cliente sem margem INSS | K27: =IFERROR(INDEX(validador!$C$2:$C$13,MATCH(J27,validador!$B$2:$B$13,0)),"") -> Cliente sem margem INSS | L27: =IF(E27="","",YEAR(E27)&""&RIGHT("0"&MONTH(E27),2)) -> 202610
A28: 021.599.410-85 | B28: CLAITON SOMAVILLA | C28: CLT IJUI | D28: 2.06 CREDIAGORA IJUI | E28: 46296.391 | F28: ProspecÃ§Ã£o | G28: camila.froes | H28: (55)996520957 | I28: (55)996520957 | J28: =IFERROR(INDEX(validador!$B$2:$B$13,MATCH(F28,validador!$A$2:$A$13,0)),"") -> Prospecção | K28: =IFERROR(INDEX(validador!$C$2:$C$13,MATCH(J28,validador!$B$2:$B$13,0)),"") -> Prospecção | L28: =IF(E28="","",YEAR(E28)&""&RIGHT("0"&MONTH(E28),2)) -> 202610
A29: 993.625.200-44 | B29: IVONE MARIA MAGERL | C29: Receptivo SCR | D29: 2.05 CREDIAGORA SANTO CRISTO | E29: 46296.392 | F29: ProspecÃ§Ã£o | G29: patricia.eu | H29: (55)35411260 | I29: (55)999464349 | J29: =IFERROR(INDEX(validador!$B$2:$B$13,MATCH(F29,validador!$A$2:$A$13,0)),"") -> Prospecção | K29: =IFERROR(INDEX(validador!$C$2:$C$13,MATCH(J29,validador!$B$2:$B$13,0)),"") -> Prospecção | L29: =IF(E29="","",YEAR(E29)&""&RIGHT("0"&MONTH(E29),2)) -> 202610
... A45: 670.939.300-34 | B45: VARONEZ WERNER | C45: TPO INSS 50,00 A 150,00 | D45: 2.14 CREDIAGORA TENENTE PORTELA | E45: 46296.401 | F45: Cliente em negociaÃ§Ã£o | G45: kelen.tnp | H45: (55)99605884800false | I45: (55)997010269 | J45: =IFERROR(INDEX(validador!$B$2:$B$13,MATCH(F45,validador!$A$2:$A$13,0)),"") -> Cliente em negociação | K45: =IFERROR(INDEX(validador!$C$2:$C$13,MATCH(J45,validador!$B$2:$B$13,0)),"") -> Ligação | L45: =IF(E45="","",YEAR(E45)&""&RIGHT("0"&MONTH(E45),2)) -> 202610
A46: 193.114.270-04 | B46: ODETE PACHECO BONORINO | C46: Receptiva SRO | D46: 2.01 CREDIAGORA SANTA ROSA | E46: 46296.401 | F46: Cliente sem margem_INSS | G46: camila.b | H46: (51)3680423200false | J46: =IFERROR(INDEX(validador!$B$2:$B$13,MATCH(F46,validador!$A$2:$A$13,0)),"") -> Cliente sem margem INSS | K46: =IFERROR(INDEX(validador!$C$2:$C$13,MATCH(J46,validador!$B$2:$B$13,0)),"") -> Cliente sem margem INSS | L46: =IF(E46="","",YEAR(E46)&""&RIGHT("0"&MONTH(E46),2)) -> 202610
A47: 244.873.090-34 | B47: ADEMAR PINTO MOREIRA | C47: CRUZ ALTA INSS 50 A 200 | D47: 3.03 CREDIAGORA CRUZ ALTA | E47: 46296.401 | F47: envio de whatsapp | G47: gabriele.sg | H47: (55)98169861100false | I47: (55)981301726 | J47: =IFERROR(INDEX(validador!$B$2:$B$13,MATCH(F47,validador!$A$2:$A$13,0)),"") -> Envio de Whatsapp | K47: =IFERROR(INDEX(validador!$C$2:$C$13,MATCH(J47,validador!$B$2:$B$13,0)),"") -> Envio de Whatsapp | L47: =IF(E47="","",YEAR(E47)&""&RIGHT("0"&MONTH(E47),2)) -> 202610
A48: 997.056.300-97 | B48: NELSI PREUSS DORNELLES | C48: Receptivo SCR | D48: 2.05 CREDIAGORA SANTO CRISTO | E48: 46296.401 | F48: ProspecÃ§Ã£o | G48: patricia.eu | H48: (55)984085014 | I48: (55)984085014 | J48: =IFERROR(INDEX(validador!$B$2:$B$13,MATCH(F48,validador!$A$2:$A$13,0)),"") -> Prospecção | K48: =IFERROR(INDEX(validador!$C$2:$C$13,MATCH(J48,validador!$B$2:$B$13,0)),"") -> Prospecção | L48: =IF(E48="","",YEAR(E48)&""&RIGHT("0"&MONTH(E48),2)) -> 202610
A49: 006.991.910-09 | B49: MARCOS RODRIGO CORREA | C49: Receptiva SAN | D49: 2.13 CREDIAGORA SANTO ANGELO | E49: 46296.401 | F49: Cliente com restriÃ§Ã£o | G49: karine.reis | H49: (51)995036565 | I49: (51)995036565 | J49: =IFERROR(INDEX(validador!$B$2:$B$13,MATCH(F49,validador!$A$2:$A$13,0)),"") -> Cliente com restrição | K49: =IFERROR(INDEX(validador!$C$2:$C$13,MATCH(J49,validador!$B$2:$B$13,0)),"") -> Cliente com restrição | L49: =IF(E49="","",YEAR(E49)&""&RIGHT("0"&MONTH(E49),2)) -> 202610
A50: 678.484.860-87 | B50: FILOMENA ROESCH | C50: TPO INSS 50,00 A 150,00 | D50: 2.14 CREDIAGORA TENENTE PORTELA | E50: 46296.401 | F50: Agendado atendimento em loja | G50: mirian.silveira | H50: (55)93616306 | I50: (51)995005798 | J50: =IFERROR(INDEX(validador!$B$2:$B$13,MATCH(F50,validador!$A$2:$A$13,0)),"") -> Agendado atendimento em loja | K50: =IFERROR(INDEX(validador!$C$2:$C$13,MATCH(J50,validador!$B$2:$B$13,0)),"") -> Ligação | L50: =IF(E50="","",YEAR(E50)&""&RIGHT("0"&MONTH(E50),2)) -> 202610
A51: 603.536.000-91 | B51: ELISANGELA FRANCO SILVEIRA | C51: CLT IJUI | D51: 2.06 CREDIAGORA IJUI | E51: 46296.401 | F51: ProspecÃ§Ã£o | G51: camila.froes | H51: (0)0 | I51: (55)992096667 | J51: =IFERROR(INDEX(validador!$B$2:$B$13,MATCH(F51,validador!$A$2:$A$13,0)),"") -> Prospecção | K51: =IFERROR(INDEX(validador!$C$2:$C$13,MATCH(J51,validador!$B$2:$B$13,0)),"") -> Prospecção | L51: =IF(E51="","",YEAR(E51)&""&RIGHT("0"&MONTH(E51),2)) -> 202610
A52: 346.835.180-15 | B52: SENAIDE SCHROER | C52: RECEPTIVA LOJA DIGITAL | D52: 3.04 LOJA DIGITAL | E52: 46296.402 | F52: Cliente sem interesse | G52: FERNANDA.B | H52: (55)991541106020false | I52: (55)991541106 | J52: =IFERROR(INDEX(validador!$B$2:$B$13,MATCH(F52,validador!$A$2:$A$13,0)),"") -> Cliente sem interesse | K52: =IFERROR(INDEX(validador!$C$2:$C$13,MATCH(J52,validador!$B$2:$B$13,0)),"") -> Ligação | L52: =IF(E52="","",YEAR(E52)&""&RIGHT("0"&MONTH(E52),2)) -> 202610
A53: 968.621.300-72 | B53: IVETE RODRIGUES CAVALLARI | C53: TPO INSS 50,00 A 150,00 | D53: 2.14 CREDIAGORA TENENTE PORTELA | E53: 46296.402 | F53: Telefone invÃ¡lido | G53: mirian.silveira | H53: (55)996047592 | I53: (55)997083947 | J53: =IFERROR(INDEX(validador!$B$2:$B$13,MATCH(F53,validador!$A$2:$A$13,0)),"") -> Telefone inválido | K53: =IFERROR(INDEX(validador!$C$2:$C$13,MATCH(J53,validador!$B$2:$B$13,0)),"") -> Telefone inválido | L53: =IF(E53="","",YEAR(E53)&""&RIGHT("0"&MONTH(E53),2)) -> 202610
A54: 011.642.730-27 | B54: CLEITON TIAGO ORTH | C54: Receptivo SCR | D54: 2.05 CREDIAGORA SANTO CRISTO | E54: 46296.403 | F54: ProspecÃ§Ã£o | G54: amanda.m | H54: (55)999674448 | I54: (55)999674448 | J54: =IFERROR(INDEX(validador!$B$2:$B$13,MATCH(F54,validador!$A$2:$A$13,0)),"") -> Prospecção | K54: =IFERROR(INDEX(validador!$C$2:$C$13,MATCH(J54,validador!$B$2:$B$13,0)),"") -> Prospecção | L54: =IF(E54="","",YEAR(E54)&""&RIGHT("0"&MONTH(E54),2)) -> 202610
A55: 382.645.440-53 | B55: GILMAR VENDRUSCOLLO | C55: TPO INSS 50,00 A 150,00 | D55: 2.14 CREDIAGORA TENENTE PORTELA | E55: 46296.403 | F55: envio de whatsapp | G55: mirian.silveira | H55: (55)996523832 | I55: (55)996523832 | J55: =IFERROR(INDEX(validador!$B$2:$B$13,MATCH(F55,validador!$A$2:$A$13,0)),"") -> Envio de Whatsapp | K55: =IFERROR(INDEX(validador!$C$2:$C$13,MATCH(J55,validador!$B$2:$B$13,0)),"") -> Envio de Whatsapp | L55: =IF(E55="","",YEAR(E55)&""&RIGHT("0"&MONTH(E55),2)) -> 202610
...

Sheet validador
A1: Status | B1: STATUS CORRETO | C1: CONSIDERAR
A2: ProspecÃ§Ã£o | B2: Prospecção | C2: Prospecção
A3: Cliente sem interesse | B3: Cliente sem interesse | C3: Ligação
A4: Cliente sem margem_INSS | B4: Cliente sem margem INSS | C4: Cliente sem margem INSS
A5: contrato ativo/ limite disponivel | B5: Contrato ativo/limite disponivel | C5: Contrato ativo/limite disponivel
A6: envio de whatsapp | B6: Envio de Whatsapp | C6: Envio de Whatsapp
A7: Aceitou NegociaÃ§Ã£o | B7: Aceitou Negociação | C7: Ligação
A8: Telefone invÃ¡lido | B8: Telefone inválido | C8: Telefone inválido
A9: Cliente com restriÃ§Ã£o | B9: Cliente com restrição | C9: Cliente com restrição
A10: Retornar ligaÃ§Ã£o | B10: Retornar ligação | C10: Retornar ligação
A11: Cliente em negociaÃ§Ã£o | B11: Cliente em negociação | C11: Ligação
A12: Agendado atendimento em loja | B12: Agendado atendimento em loja | C12: Ligação
A13: FALECIDO | B13: Falecido | C13: Falecido

Sheet onde_exportar
B2: Panorama >>
B3: Click na logo Crediagora >>
B13: Substituir apenas mês atual >>
